Workbook

Sheet Danh Sách Tổng KH
A1: 763939009 | B1: Nguyễn Văn Nhu
A2: 939640407 | B2: Trần Thị Thanh Thủy
A3: 932929119 | B3: Phạm Hoài Nam
A4: 901059299 | B4: Nhan Thanh Nhân
A5: 939563439 | B5: Trân nguyen thanh nam
A6: 797380699 | B6: Trần Thanh Hưng
A7: 932919113 | B7: Nguyễn Minh Chí
A8: 939279234 | B8: Bùi Thành Đạt
A9: 932929916 | B9: Lê Thị Anh Thư
A10: 933599878 | B10: Lê Kha Nam
A11: 908072288 | B11: Lê Kha Nam
A12: 766802288 | B12: Lê Kha Nam
... A447: 907921720 | B447: Đào Thị Yến Nhi
A448: 9.07E+08 | B448: Hồng Tấn Thành
A449: 939523663 | B449: Huỳnh Thanh Phong
A450: 907631964 | B450: Lê Phát Đạt
A451: 939083539 | B451: Lê Văn Đông
A452: 931874342 | B452: Nghiêm Tuấn Khải
A453: 901223168 | B453: Nguyễn Thị Thanh Thúy
A454: 901059186 | B454: Nguyễn Công Thức
A455: 939093195 | B455: Nguyễn Đặng Quang Vinh
A456: 939696238 | B456: Nguyễn Đặng Quang Vinh
A457: 939197969 | B457: Nguyễn Ngọc Đức
A458: 931091819 | B458: Nguyễn Thanh Dũng
A459: 776825361 | B459: Nguyễn Văn Thanh Dũng
A460: 909151313 | B460: Nguyễn Thanh Tuấn
... A547: 762952593 | B547: Tạ Ánh Nguyệt

Sheet Danh Sách Hủy Đơn
A1: ="Đơn Hoàn Tiền Trong Tháng " &MONTH(TODAY()) -> Đơn Hoàn Tiền Trong Tháng 10 | G1: =SUMIF($E$3:$E948,G2,$C$3:$C948) -> 22250000 | H1: =SUMIF($E$3:$E948,H2,$C$3:$C948) -> 12390000
A2: SĐT | B2: Tên Khách Hàng | C2: Số Tiền Hủy | D2: Ngày Hủy | E2: Hình Thức Nạp | F2: Lý do | G2: Nạp Hộ | H2: OTP
A3: 931776876 | B3: =IF(A3<>"", VLOOKUP(A3,'Danh Sách Tổng KH'!$A$1:$B$547,2,0),"") -> Trần Xuân Đông Pha | C3: 90000 | D3: 45520 | E3: OTP | F3: Trang yêu cầu hủy
A4: 931070719 | B4: =IF(A4<>"", VLOOKUP(A4,'Danh Sách Tổng KH'!$A$1:$B$547,2,0),"") -> HKD Cơ Sở Nhôm Cao Cấp Tiến Phát | C4: 100000 | D4: 45520 | E4: Nạp hộ | F4: DS dưới huyện hủy đơn gạch cước
A5: 931070729 | B5: =IF(A5<>"", VLOOKUP(A5,'Danh Sách Tổng KH'!$A$1:$B$547,2,0),"") -> HKD Cơ Sở Nhôm Cao Cấp Tiến Phát | C5: 100000 | D5: 45520 | E5: Nạp hộ | F5: DS dưới huyện hủy đơn gạch cước
A6: 778664664 | B6: =IF(A6<>"", VLOOKUP(A6,'Danh Sách Tổng KH'!$A$1:$B$547,2,0),"") -> Đào Nguyễn Dũng | C6: 250000 | D6: 45520 | E6: Nạp hộ | F6: DS dưới huyện hủy đơn gạch cước
A7: 799688778 | B7: =IF(A7<>"", VLOOKUP(A7,'Danh Sách Tổng KH'!$A$1:$B$547,2,0),"") -> Nguyễn Đại Sơn | C7: 100000 | D7: 45520 | E7: Nạp hộ | F7: DS dưới huyện hủy đơn gạch cước
A8: 899167869 | B8: =IF(A8<>"", VLOOKUP(A8,'Danh Sách Tổng KH'!$A$1:$B$547,2,0),"") -> Đặng Thị Minh Giang | C8: 150000 | D8: 45520 | E8: Nạp hộ | F8: DS dưới huyện hủy đơn gạch cước
A9: 931091686 | B9: =IF(A9<>"", VLOOKUP(A9,'Danh Sách Tổng KH'!$A$1:$B$547,2,0),"") -> Bùi Thành Đạt | C9: 150000 | D9: 45520 | E9: Nạp hộ | F9: DS dưới huyện hủy đơn gạch cước
A10: 907613686 | B10: =IF(A10<>"", VLOOKUP(A10,'Danh Sách Tổng KH'!$A$1:$B$547,2,0),"") -> Bùi Thành Đạt | C10: 150000 | D10: 45520 | E10: Nạp hộ | F10: DS dưới huyện hủy đơn gạch cước
A11: 939294334 | B11: =IF(A11<>"", VLOOKUP(A11,'Danh Sách Tổng KH'!$A$1:$B$547,2,0),"") -> Đỗ Thị Bích Huệ | C11: 150000 | D11: 45520 | E11: Nạp hộ | F11: DS dưới huyện hủy đơn gạch cước
A12: 901008988 | B12: =IF(A12<>"", VLOOKUP(A12,'Danh Sách Tổng KH'!$A$1:$B$547,2,0),"") -> Trần Thị Thanh Nghĩa | C12: 100000 | D12: 45520 | E12: Nạp hộ | F12: DS dưới huyện hủy đơn gạch cước
A13: 939791979 | B13: =IF(A13<>"", VLOOKUP(A13,'Danh Sách Tổng KH'!$A$1:$B$547,2,0),"") -> Nguyễn Hồng Xuân | C13: 50000 | D13: 45520 | E13: Nạp hộ | F13: DS dưới huyện hủy đơn gạch cước
A14: 939696834 | B14: =IF(A14<>"", VLOOKUP(A14,'Danh Sách Tổng KH'!$A$1:$B$547,2,0),"") -> Nguyễn Thị Mộng Ngọc | C14: 350000 | D14: 45520 | E14: Nạp hộ | F14: DS dưới huyện hủy đơn gạch cước
... A120: 939078082 | B120: =IF(A120<>"", VLOOKUP(A120,'Danh Sách Tổng KH'!$A$1:$B$547,2,0),"") -> Huỳnh Thanh Vũ | C120: 180000 | D120: 45653 | E120: OTP | F120: Huỷ gạch Mobipay
A121: 795468417 | B121: =IF(A121<>"", VLOOKUP(A121,'Danh Sách Tổng KH'!$A$1:$B$547,2,0),"") -> Lê Trung Tín | C121: 100000
A122: 901223168 | B122: =IF(A122<>"", VLOOKUP(A122,'Danh Sách Tổng KH'!$A$1:$B$547,2,0),"") -> Nguyễn Thị Thanh Thúy | C122: 200000 | D122: 45665 | E122: OTP | F122: Khách chuyển trả trước
A123: 787885151 | B123: =IF(A123<>"", VLOOKUP(A123,'Danh Sách Tổng KH'!$A$1:$B$547,2,0),"") -> Phan Phạm Ngọc Trân | C123: 400000 | D123: 45670 | E123: OTP | F123: Gạch MGO
A124: 939197722 | B124: =IF(A124<>"", VLOOKUP(A124,'Danh Sách Tổng KH'!$A$1:$B$547,2,0),"") -> Lê Hoàng Việt | C124: 200000 | D124: 45678 | E124: OTP | F124: Trang yêu cầu hủy
A125: 932993088 | B125: =IF(A125<>"", VLOOKUP(A125,'Danh Sách Tổng KH'!$A$1:$B$547,2,0),"") -> Quan Thị Lan Hương | C125: 160000 | D125: 45685 | E125: OTP | F125: Trang yêu cầu hủy
A126: 767575599 | B126: =IF(A126<>"", VLOOKUP(A126,'Danh Sách Tổng KH'!$A$1:$B$547,2,0),"") -> Nguyễn Hữu Lộc | C126: 30000 | D126: 45685 | E126: OTP | F126: Trang yêu cầu hủy
A127: 787976362 | B127: =IF(A127<>"", VLOOKUP(A127,'Danh Sách Tổng KH'!$A$1:$B$547,2,0),"") -> Nguyễn Tuấn Tài | C127: 150000 | D127: 45692 | E127: OTP | F127: Trang yêu cầu hủy
B128: =IF(A128<>"", VLOOKUP(A128,'Danh Sách Tổng KH'!$A$1:$B$547,2,0),"")
A129: 939791721 | B129: =IF(A129<>"", VLOOKUP(A129,'Danh Sách Tổng KH'!$A$1:$B$547,2,0),"") -> Hoàng Lê Trang Đài | C129: 150000 | D129: 45697 | E129: Nạp hộ | F129: Thuê bao bị khóa
A130: 906665971 | B130: =IF(A130<>"", VLOOKUP(A130,'Danh Sách Tổng KH'!$A$1:$B$547,2,0),"") -> Trần Thị Thùy Trang | C130: 890000 | D130: 45729 | E130: Nạp hộ | F130: Chuyển Mobipay vì lời 3 chấm
A131: 905252689 | B131: =IF(A131<>"", VLOOKUP(A131,'Danh Sách Tổng KH'!$A$1:$B$547,2,0),"") -> Nguyễn Hữu Vũ | C131: 210000 | D131: 45734 | E131: Nạp hộ | F131: Thuê bao của Bạn quý khách phải hoạt động 2 chiều tại thời điểm sử dụng tính năng
A132: 936343799 | B132: =IF(A132<>"", VLOOKUP(A132,'Danh Sách Tổng KH'!$A$1:$B$547,2,0),"") -> Trần Văn Leo | C132: 200000 | D132: 45734 | E132: Nạp hộ | F132: Thuê bao của Bạn quý khách phải hoạt động 2 chiều tại thời điểm sử dụng tính năng
A133: 931010215 | B133: =IF(A133<>"", VLOOKUP(A133,'Danh Sách Tổng KH'!$A$1:$B$547,2,0),"") -> Nguyễn Thành Công | C133: 330000 | D133: 45742 | E133: OTP | F133: Trang yêu cầu huỷ
A134: 939590959 | B134: =IF(A134<>"", VLOOKUP(A134,'Danh Sách Tổng KH'!$A$1:$B$547,2,0),"") -> Khưu Thanh Hưng | C134: 80000 | D134: 45742 | E134: OTP | F134: Trang yêu cầu huỷ
A135: 939772712 | B135: =IF(A135<>"", VLOOKUP(A135,'Danh Sách Tổng KH'!$A$1:$B$547,2,0),"") -> Tô Hải Vân | C135: 300000 | D135: 45763 | E135: Nạp hộ | F135: KH thanh toán rồi
A136: 906648240 | B136: =IF(A136<>"", VLOOKUP(A136,'Danh Sách Tổng KH'!$A$1:$B$547,2,0),"") -> Huỳnh Thanh Sơn | C136: 120000 | D136: 45773 | E136: OTP | F136: Gạch cước ko lấy dc OTP
A137: 939969498 | B137: =IF(A137<>"", VLOOKUP(A137,'Danh Sách Tổng KH'!$A$1:$B$547,2,0),"") -> HỘ KINH DOANH RIO | C137: 270000 | D137: 45775 | E137: Nạp hộ | F137: Hết thẻ tháng này gạch cước dùm tui
A138: 907404881 | B138: =IF(A138<>"", VLOOKUP(A138,'Danh Sách Tổng KH'!$A$1:$B$547,2,0),"") -> Nguyễn Thanh Tuyền | C138: 170000 | D138: 45786 | E138: OTP | F138: Gạch MGO
A139: 932803632 | B139: =IF(A139<>"", VLOOKUP(A139,'Danh Sách Tổng KH'!$A$1:$B$547,2,0),"") -> Nguyễn Thị Nguyệt | C139: 150000 | D139: 45798 | E139: OTP | F139: KH thanh toán rồi
A140: 901791328 | B140: =IF(A140<>"", VLOOKUP(A140,'Danh Sách Tổng KH'!$A$1:$B$547,2,0),"") -> NGUYỄN MINH TÂM | C140: 150000 | D140: 45804 | E140: OTP | F140: KH thanh toán rồi
... A188: 706706038 | B188: =IF(A188<>"", VLOOKUP(A188,'Danh Sách Tổng KH'!$A$1:$B$547,2,0),"") -> Lê Si MuômL | C188: 100000 | D188: 46157 | E188: Nạp hộ | F188: Thuê bao bị khóa
A189: 931793117 | B189: =IF(A189<>"", VLOOKUP(A189,'Danh Sách Tổng KH'!$A$1:$B$547,2,0),"") -> Đặng Thanh Thùy | C189: 250000 | D189: 46199 | E189: OTP
A190: 931782783 | B190: =IF(A190<>"", VLOOKUP(A190,'Danh Sách Tổng KH'!$A$1:$B$547,2,0),"") -> Nguyễn Minh Chí | C190: 200000 | D190: 46199 | E190: OTP
A191: 939689659 | B191: =IF(A191<>"", VLOOKUP(A191,'Danh Sách Tổng KH'!$A$1:$B$547,2,0),"") -> Huỳnh Tuấn Kiệt | C191: 100000 | D191: 46250 | E191: OTP | F191: KH nạp tiền
A192: 901084883 | B192: =IF(A192<>"", VLOOKUP(A192,'Danh Sách Tổng KH'!$A$1:$B$547,2,0),"") -> Phạm Đồng Thịnh | C192: 10000 | D192: 46254 | E192: Nạp hộ | F192: Web mới chạy được 290k hết thẻ tháng
...

Sheet Danh Sách Phát Sinh
A1: ="Đơn Phát Sinh Trong Tháng " &MONTH(TODAY()) -> Đơn Phát Sinh Trong Tháng 10 | G1: =SUMIF($E$3:$E999,G2,$C$3:$C999) -> 3030000 | H1: =SUMIF($E$3:$E999,H2,$C$3:$C999) -> 610000
A2: SĐT | B2: Tên Khách Hàng | C2: Số Tiền | D2: Ngày Lên Đơn | E2: Hình Thức Nạp | F2: Số Chấm Lời | G2: Nạp Hộ | H2: OTP
A3: 939790925 | B3: =IF(A3<>"", VLOOKUP(A3,'Danh Sách Tổng KH'!$A$1:$B$547,2,0),"") -> Lê Thị Thu Thủy | C3: 100000 | D3: 45463 | E3: Nạp Hộ | F3: 6
A4: 787979164 | B4: =IF(A4<>"", VLOOKUP(A4,'Danh Sách Tổng KH'!$A$1:$B$547,2,0),"") -> Châu Vĩnh Toàn | C4: 150000 | D4: 45463 | E4: Nạp Hộ | F4: 6
A5: 911468998 | B5: =IF(A5<>"", VLOOKUP(A5,'Danh Sách Tổng KH'!$A$1:$B$547,2,0),"") -> thanh chợ agri | C5: 100000 | D5: 45479 | E5: Nạp Hộ
A6: 939517521 | B6: =IF(A6<>"", VLOOKUP(A6,'Danh Sách Tổng KH'!$A$1:$B$547,2,0),"") -> Nguyễn Thị Bé Chiều | C6: 410000 | D6: 45522 | E6: OTP | F6: 8
A7: 939930030 | B7: =IF(A7<>"", VLOOKUP(A7,'Danh Sách Tổng KH'!$A$1:$B$547,2,0),"") -> Nguyễn Phúc Thiện | C7: 150000 | D7: 45543 | E7: Nạp hộ | F7: 6
A8: 977283949 | B8: =IF(A8<>"", VLOOKUP(A8,'Danh Sách Tổng KH'!$A$1:$B$547,2,0),"") -> Trần Thị Mộng Cầm | C8: 200000 | D8: 45543 | E8: Nạp hộ | F8: 6
A9: 939359580 | B9: =IF(A9<>"", VLOOKUP(A9,'Danh Sách Tổng KH'!$A$1:$B$547,2,0),"") -> Trần Thị Mỹ Cầm | C9: 250000 | D9: 45543 | E9: Nạp hộ | F9: 6
A10: 932929119 | B10: =IF(A10<>"", VLOOKUP(A10,'Danh Sách Tổng KH'!$A$1:$B$547,2,0),"") -> Phạm Hoài Nam | C10: 200000 | D10: 45543 | E10: Nạp hộ | F10: 5
A11: 939946379 | B11: =IF(A11<>"", VLOOKUP(A11,'Danh Sách Tổng KH'!$A$1:$B$547,2,0),"") -> Võ Anh Hoàng | C11: 200000 | D11: 45543 | E11: Nạp hộ | F11: 6
A12: 794384630 | B12: =IF(A12<>"", VLOOKUP(A12,'Danh Sách Tổng KH'!$A$1:$B$547,2,0),"") -> Phan Thị Tô Vy | C12: 150000 | D12: 45543 | E12: Nạp hộ | F12: 6
A13: 939112983 | B13: =IF(A13<>"", VLOOKUP(A13,'Danh Sách Tổng KH'!$A$1:$B$547,2,0),"") -> Nguyễn Thị Kim Ngân Mật ong LP | C13: 100000 | D13: 45549 | E13: OTP | F13: Thế đơn cho Nguyễn Xuân Thu
A14: 911468998 | B14: =IF(A14<>"", VLOOKUP(A14,'Danh Sách Tổng KH'!$A$1:$B$547,2,0),"") -> thanh chợ agri | C14: 100000 | D14: 45570 | E14: Nạp hộ | F14: 6
A15: 939339239 | B15: =IF(A15<>"", VLOOKUP(A15,'Danh Sách Tổng KH'!$A$1:$B$547,2,0),"") -> Võ Hoàng Phương Thư | C15: 250000 | D15: 45570 | E15: Nạp hộ | F15: 6
A16: 939112983 | B16: =IF(A16<>"", VLOOKUP(A16,'Danh Sách Tổng KH'!$A$1:$B$547,2,0),"") -> Nguyễn Thị Kim Ngân Mật ong LP | C16: 100000 | D16: 45620 | E16: OTP
A17: 776505070 | B17: =IF(A17<>"", VLOOKUP(A17,'Danh Sách Tổng KH'!$A$1:$B$547,2,0),"") -> Nguyễn Thị Quí VLXD Thành Nhơn | C17: 170000 | D17: 45761 | E17: Nạp hộ | F17: 5
A18: 898058958 | B18: =IF(A18<>"", VLOOKUP(A18,'Danh Sách Tổng KH'!$A$1:$B$547,2,0),"") -> Nguyễn Kim Thảo | C18: 150000 | D18: 45761 | E18: Nạp hộ | F18: 5
A19: 931069089 | B19: =IF(A19<>"", VLOOKUP(A19,'Danh Sách Tổng KH'!$A$1:$B$547,2,0),"") -> Công Ty TNHH MTV Đức Phát Hoàng Gia | C19: 250000 | D19: 45761 | E19: Nạp hộ | F19: 5
A20: 939979101 | B20: =IF(A20<>"", VLOOKUP(A20,'Danh Sách Tổng KH'!$A$1:$B$547,2,0),"") -> Lê Nguyễn Hồng Nhung | C20: 160000 | D20: 45789 | E20: Nạp hộ | F20: 6
A21: 797380699 | B21: =IF(A21<>"", VLOOKUP(A21,'Danh Sách Tổng KH'!$A$1:$B$547,2,0),"") -> Trần Thanh Hưng | C21: 150000 | D21: 46097 | E21: Nạp hộ | F21: 6
A22: 901767878 | B22: =IF(A22<>"", VLOOKUP(A22,'Danh Sách Tổng KH'!$A$1:$B$547,2,0),"") -> Thầu Lý | C22: 300000 | D22: 46109 | E22: Nạp hộ
B23: =IF(A23<>"", VLOOKUP(A23,'Danh Sách Tổng KH'!$A$1:$B$547,2,0),"")
B24: =IF(A24<>"", VLOOKUP(A24,'Danh Sách Tổng KH'!$A$1:$B$547,2,0),"")
B25: =IF(A25<>"", VLOOKUP(A25,'Danh Sách Tổng KH'!$A$1:$B$547,2,0),"")
B26: =IF(A26<>"", VLOOKUP(A26,'Danh Sách Tổng KH'!$A$1:$B$547,2,0),"")
B27: =IF(A27<>"", VLOOKUP(A27,'Danh Sách Tổng KH'!$A$1:$B$547,2,0),"")
B28: =IF(A28<>"", VLOOKUP(A28,'Danh Sách Tổng KH'!$A$1:$B$547,2,0),"")
B29: =IF(A29<>"", VLOOKUP(A29,'Danh Sách Tổng KH'!$A$1:$B$547,2,0),"")
B30: =IF(A30<>"", VLOOKUP(A30,'Danh Sách Tổng KH'!$A$1:$B$547,2,0),"")
B31: =IF(A31<>"", VLOOKUP(A31,'Danh Sách Tổng KH'!$A$1:$B$547,2,0),"")
B32: =IF(A32<>"", VLOOKUP(A32,'Danh Sách Tổng KH'!$A$1:$B$547,2,0),"")
B33: =IF(A33<>"", VLOOKUP(A33,'Danh Sách Tổng KH'!$A$1:$B$547,2,0),"")
B34: =IF(A34<>"", VLOOKUP(A34,'Danh Sách Tổng KH'!$A$1:$B$547,2,0),"")
... B55: =IF(A55<>"", VLOOKUP(A55,'Danh Sách Tổng KH'!$A$1:$B$547,2,0),"")

Sheet Danh Sách Đơn Chưa Cho Chạy
A1: ="ĐƠN CHƯA CHO CHẠY TRONG THÁNG " &MONTH(TODAY()) -> ĐƠN CHƯA CHO CHẠY TRONG THÁNG 10
A2: SĐT | B2: Tên Khách Hàng | C2: Trạng Thái | D2: Số Tiền | E2: Cho Chạy | F2: Thành công
A3: 907602719 | B3: =IF(A3<>"", VLOOKUP(A3,'Danh Sách Tổng KH'!$A$1:$B$547,2,0),"") -> Nguyễn Thị Thùy Loan | C3: =IF(B3<>"","Chưa cho lên đơn","") -> Chưa cho lên đơn | D3: 160000 | E3: x | F3: Đã lên đơn
A4: 907998131 | B4: =IF(A4<>"", VLOOKUP(A4,'Danh Sách Tổng KH'!$A$1:$B$547,2,0),"") -> Nguyễn Xuân Thu | C4: =IF(B4<>"","Chưa cho lên đơn","") -> Chưa cho lên đơn | D4: 120000 | E4: x | F4: Đã lên đơn
A5: 936343799 | B5: =IF(A5<>"", VLOOKUP(A5,'Danh Sách Tổng KH'!$A$1:$B$547,2,0),"") -> Trần Văn Leo | C5: =IF(B5<>"","Chưa cho lên đơn","") -> Chưa cho lên đơn | D5: 200000 | E5: x | F5: Đã lên đơn
A6: 905252689 | B6: =IF(A6<>"", VLOOKUP(A6,'Danh Sách Tổng KH'!$A$1:$B$547,2,0),"") -> Nguyễn Hữu Vũ | C6: =IF(B6<>"","Chưa cho lên đơn","") -> Chưa cho lên đơn | D6: 220000 | E6: x | F6: Đã lên đơn
A7: 907703739 | B7: =IF(A7<>"", VLOOKUP(A7,'Danh Sách Tổng KH'!$A$1:$B$547,2,0),"") -> Lê Thị Hồng Sang | C7: =IF(B7<>"","Chưa cho lên đơn","") -> Chưa cho lên đơn | D7: 160000 | E7: x | F7: Đã lên đơn
A8: 939790925 | B8: =IF(A8<>"", VLOOKUP(A8,'Danh Sách Tổng KH'!$A$1:$B$547,2,0),"") -> Lê Thị Thu Thủy | C8: =IF(B8<>"","Chưa cho lên đơn","") -> Chưa cho lên đơn | D8: 100000 | E8: x | F8: Đã lên đơn
A9: 909320563 | B9: =IF(A9<>"", VLOOKUP(A9,'Danh Sách Tổng KH'!$A$1:$B$547,2,0),"") -> Nguyễn Thị ái Vi | C9: =IF(B9<>"","Chưa cho lên đơn","") -> Chưa cho lên đơn | D9: 1390000 | E9: xx | F9: Đã lên đơn
A10: 939987111 | B10: =IF(A10<>"", VLOOKUP(A10,'Danh Sách Tổng KH'!$A$1:$B$547,2,0),"") -> Nguyễn Thái An | C10: =IF(B10<>"","Chưa cho lên đơn","") -> Chưa cho lên đơn | D10: 1050000 | E10: xx | F10: Đã lên đơn
A11: 787955556 | B11: =IF(A11<>"", VLOOKUP(A11,'Danh Sách Tổng KH'!$A$1:$B$547,2,0),"") -> Huỳnh Xuân Khương | C11: =IF(B11<>"","Chưa cho lên đơn","") -> Chưa cho lên đơn | D11: 210000 | E11: xx | F11: Đã lên đơn
A12: 902329258 | B12: =IF(A12<>"", VLOOKUP(A12,'Danh Sách Tổng KH'!$A$1:$B$547,2,0),"") -> Trần Thị Dung | C12: =IF(B12<>"","Chưa cho lên đơn","") -> Chưa cho lên đơn | D12: 300000 | E12: xxx | F12: Đã lên đơn
A13: 763222366 | B13: =IF(A13<>"", VLOOKUP(A13,'Danh Sách Tổng KH'!$A$1:$B$547,2,0),"") -> Phan Văn Tưởng | C13: =IF(B13<>"","Chưa cho lên đơn","") -> Chưa cho lên đơn | D13: =160000 -> 160000 | E13: xxxx | F13: Đã lên đơn
A14: 702896623 | B14: =IF(A14<>"", VLOOKUP(A14,'Danh Sách Tổng KH'!$A$1:$B$547,2,0),"") -> Nguyễn Thị Cẩm Vân | C14: =IF(B14<>"","Chưa cho lên đơn","") -> Chưa cho lên đơn | D14: 120000 | E14: xxxx | F14: Đã lên đơn
A15: 939068036 | B15: =IF(A15<>"", VLOOKUP(A15,'Danh Sách Tổng KH'!$A$1:$B$547,2,0),"") -> Nguyễn Thị Trúc Phương kế út bơm cát | C15: =IF(B15<>"","Chưa cho lên đơn","") -> Chưa cho lên đơn | D15: 150000 | E15: xxxx | F15: Đã lên đơn
A16: 939890980 | B16: =IF(A16<>"", VLOOKUP(A16,'Danh Sách Tổng KH'!$A$1:$B$547,2,0),"") -> Nguyễn Thanh Hải Tuấn sắt p3 | C16: =IF(B16<>"","Chưa cho lên đơn","") -> Chưa cho lên đơn | D16: 100000 | E16: xxxx | F16: Đã lên đơn
A17: 939865286 | B17: =IF(A17<>"", VLOOKUP(A17,'Danh Sách Tổng KH'!$A$1:$B$547,2,0),"") -> Lê Văn Quân hẻm yagami | C17: =IF(B17<>"","Chưa cho lên đơn","") -> Chưa cho lên đơn | D17: 210000 | E17: xxxx | F17: Đã lên đơn
A18: 937456721 | B18: =IF(A18<>"", VLOOKUP(A18,'Danh Sách Tổng KH'!$A$1:$B$547,2,0),"") -> Nguyễn Hoàng Nhật | C18: =IF(B18<>"","Chưa cho lên đơn","") -> Chưa cho lên đơn | D18: 150000 | E18: xxxxx | F18: Đã lên đơn
A19: 977283949 | B19: =IF(A19<>"", VLOOKUP(A19,'Danh Sách Tổng KH'!$A$1:$B$547,2,0),"") -> Trần Thị Mộng Cầm | C19: =IF(B19<>"","Chưa cho lên đơn","") -> Chưa cho lên đơn | D19: 230000 | E19: xxxxx | F19: Đã lên đơn
A20: 939359580 | B20: =IF(A20<>"", VLOOKUP(A20,'Danh Sách Tổng KH'!$A$1:$B$547,2,0),"") -> Trần Thị Mỹ Cầm | C20: =IF(B20<>"","Chưa cho lên đơn","") -> Chưa cho lên đơn | D20: 260000 | E20: xxxxx | F20: Đã lên đơn
A21: 907306169 | B21: =IF(A21<>"", VLOOKUP(A21,'Danh Sách Tổng KH'!$A$1:$B$547,2,0),"") -> Nguyễn Thị Phẩm | C21: =IF(B21<>"","Chưa cho lên đơn","") -> Chưa cho lên đơn | D21: 100000 | E21: xxxxx | F21: Đã lên đơn
A22: 788975319 | B22: =IF(A22<>"", VLOOKUP(A22,'Danh Sách Tổng KH'!$A$1:$B$547,2,0),"") -> Trần Minh Vũ nhà xe Huệ | C22: =IF(B22<>"","Chưa cho lên đơn","") -> Chưa cho lên đơn | D22: 110000 | E22: xxxxx | F22: Đã lên đơn
A23: 703999709 | B23: =IF(A23<>"", VLOOKUP(A23,'Danh Sách Tổng KH'!$A$1:$B$547,2,0),"") -> Nguyễn Hoàng Tâm Hạnh wile | C23: =IF(B23<>"","Chưa cho lên đơn","") -> Chưa cho lên đơn | D23: 240000 | E23: xxxxxx | F23: Đã lên đơn
A24: 937598199 | B24: =IF(A24<>"", VLOOKUP(A24,'Danh Sách Tổng KH'!$A$1:$B$547,2,0),"") -> Phạm Thị Hồng Gấm công viên mậu thân | C24: =IF(B24<>"","Chưa cho lên đơn","") -> Chưa cho lên đơn | D24: 170000 | E24: xxxxxx | F24: Đã lên đơn
A25: 907982798 | B25: =IF(A25<>"", VLOOKUP(A25,'Danh Sách Tổng KH'!$A$1:$B$547,2,0),"") -> Trần Ánh Ngọc zalo Nguyễn Phước Thiện | C25: =IF(B25<>"","Chưa cho lên đơn","") -> Chưa cho lên đơn | D25: 150000 | E25: xxxxxx | F25: Đã lên đơn
... A37: 939318308 | B37: =IF(A37<>"", VLOOKUP(A37,'Danh Sách Tổng KH'!$A$1:$B$547,2,0),"") -> Nguyễn Trần Phước Thịnh | C37: =IF(B37<>"","Chưa cho lên đơn","") -> Chưa cho lên đơn | D37: 160000 | E37: xxxxxxx | F37: Đã lên đơn
A38: 907917191 | B38: =IF(A38<>"", VLOOKUP(A38,'Danh Sách Tổng KH'!$A$1:$B$547,2,0),"") -> Phan Thành Long | C38: =IF(B38<>"","Chưa cho lên đơn","") -> Chưa cho lên đơn | D38: 210000
A39: 762952593 | B39: =IF(A39<>"", VLOOKUP(A39,'Danh Sách Tổng KH'!$A$1:$B$547,2,0),"") -> Tạ Ánh Nguyệt | C39: =IF(B39<>"","Chưa cho lên đơn","") -> Chưa cho lên đơn | D39: 100000
A40: 932812977 | B40: =IF(A40<>"", VLOOKUP(A40,'Danh Sách Tổng KH'!$A$1:$B$547,2,0),"") -> Ngô Hồng Diệp | C40: =IF(B40<>"","Chưa cho lên đơn","") -> Chưa cho lên đơn | D40: 150000
A41: 907570775 | B41: =IF(A41<>"", VLOOKUP(A41,'Danh Sách Tổng KH'!$A$1:$B$547,2,0),"") -> Trần Hoàng Phúc suối mơ p5 | C41: =IF(B41<>"","Chưa cho lên đơn","") -> Chưa cho lên đơn | D41: 180000
A42: 939284004 | B42: =IF(A42<>"", VLOOKUP(A42,'Danh Sách Tổng KH'!$A$1:$B$547,2,0),"") -> Công Ty Trách Nhiệm Hữu Hạn Lê Kim | C42: =IF(B42<>"","Chưa cho lên đơn","") -> Chưa cho lên đơn | D42: 50000
A43: 909244004 | B43: =IF(A43<>"", VLOOKUP(A43,'Danh Sách Tổng KH'!$A$1:$B$547,2,0),"") -> Công Ty Trách Nhiệm Hữu Hạn Lê Kim | C43: =IF(B43<>"","Chưa cho lên đơn","") -> Chưa cho lên đơn | D43: 50000
A44: 901244004 | B44: =IF(A44<>"", VLOOKUP(A44,'Danh Sách Tổng KH'!$A$1:$B$547,2,0),"") -> Công Ty Trách Nhiệm Hữu Hạn Lê Kim | C44: =IF(B44<>"","Chưa cho lên đơn","") -> Chưa cho lên đơn | D44: 210000
A45: 939586066 | B45: =IF(A45<>"", VLOOKUP(A45,'Danh Sách Tổng KH'!$A$1:$B$547,2,0),"") -> Nguyễn Thị Quỳnh Anh ban dân tộc | C45: =IF(B45<>"","Chưa cho lên đơn","") -> Chưa cho lên đơn | D45: 150000
A46: 939068963 | B46: =IF(A46<>"", VLOOKUP(A46,'Danh Sách Tổng KH'!$A$1:$B$547,2,0),"") -> Nguyễn Thị Hồng Cúc bãi cọc cầu tân hữu mới | C46: =IF(B46<>"","Chưa cho lên đơn","") -> Chưa cho lên đơn | D46: 90000
A47: 939637899 | B47: =IF(A47<>"", VLOOKUP(A47,'Danh Sách Tổng KH'!$A$1:$B$547,2,0),"") -> Trần Phương Trang | C47: =IF(B47<>"","Chưa cho lên đơn","") -> Chưa cho lên đơn | D47: 210000
A48: 704797978 | B48: =IF(A48<>"", VLOOKUP(A48,'Danh Sách Tổng KH'!$A$1:$B$547,2,0),"") -> Võ Văn Kiệt | C48: =IF(B48<>"","Chưa cho lên đơn","") -> Chưa cho lên đơn | D48: 100000 | E48: x | F48: Đã lên đơn
A49: 907880007 | B49: =IF(A49<>"", VLOOKUP(A49,'Danh Sách Tổng KH'!$A$1:$B$547,2,0),"") -> Võ Văn Kiệt | C49: =IF(B49<>"","Chưa cho lên đơn","") -> Chưa cho lên đơn | D49: 250000 | E49: x | F49: Đã lên đơn
A50: 776505199 | B50: =IF(A50<>"", VLOOKUP(A50,'Danh Sách Tổng KH'!$A$1:$B$547,2,0),"") -> Phạm Thị Mỹ Ái | C50: =IF(B50<>"","Chưa cho lên đơn","") -> Chưa cho lên đơn | D50: 200000 | E50: xxx | F50: Đã lên đơn
A51: 907646875 | B51: =IF(A51<>"", VLOOKUP(A51,'Danh Sách Tổng KH'!$A$1:$B$547,2,0),"") -> Nguyễn Thị Đan Thanh | C51: =IF(B51<>"","Chưa cho lên đơn","") -> Chưa cho lên đơn | D51: 270000 | E51: xxx | F51: Đã lên đơn
...

Sheet Trạng thái Đơn OTP
A1: ="TRANG KIỂM TRA TRẠNG THÁI CHO CHẠY OTP TRONG THÁNG " &MONTH(TODAY()) -> TRANG KIỂM TRA TRẠNG THÁI CHO CHẠY OTP TRONG THÁNG 10
A2: 939078082 | B2: =IF(A2<>"", VLOOKUP(A2,'Danh Sách Tổng KH'!$A$1:$B$547,2,0),"") -> Huỳnh Thanh Vũ | C2: =IF(E2="x","Đã nạp","Lấy OTP") -> Lấy OTP | D2: 250000 | F2: =A2&","&D2 -> 939078082,250000
A3: 932804935 | B3: =IF(A3<>"", VLOOKUP(A3,'Danh Sách Tổng KH'!$A$1:$B$547,2,0),"") -> Biện Kim Thủy | C3: =IF(E3="x","Đã nạp","Lấy OTP") -> Lấy OTP | D3: 50000 | F3: =A3&","&D3 -> 932804935,50000
A4: 903687189 | B4: =IF(A4<>"", VLOOKUP(A4,'Danh Sách Tổng KH'!$A$1:$B$547,2,0),"") -> Mai Bích Liên | C4: =IF(E4="x","Đã nạp","Lấy OTP") -> Đã nạp | D4: 200000 | E4: x | F4: =A4&","&D4 -> 903687189,200000
A5: 908055725 | B5: =IF(A5<>"", VLOOKUP(A5,'Danh Sách Tổng KH'!$A$1:$B$547,2,0),"") -> Nguyễn Thị Xuân Liễu | C5: =IF(E5="x","Đã nạp","Lấy OTP") -> Lấy OTP | D5: 150000 | F5: =A5&","&D5 -> 908055725,150000
A6: 902933446 | B6: =IF(A6<>"", VLOOKUP(A6,'Danh Sách Tổng KH'!$A$1:$B$547,2,0),"") -> Châu Thạch Đời | C6: =IF(E6="x","Đã nạp","Lấy OTP") -> Lấy OTP | D6: 150000 | F6: =A6&","&D6 -> 902933446,150000
A7: 939364064 | B7: =IF(A7<>"", VLOOKUP(A7,'Danh Sách Tổng KH'!$A$1:$B$547,2,0),"") -> Huỳnh Hữu Quang | C7: =IF(E7="x","Đã nạp","Lấy OTP") -> Đã nạp | D7: 150000 | E7: x | F7: =A7&","&D7 -> 939364064,150000
A8: 901020266 | B8: =IF(A8<>"", VLOOKUP(A8,'Danh Sách Tổng KH'!$A$1:$B$547,2,0),"") -> Huỳnh Ngọc Thủy Tiên | C8: =IF(E8="x","Đã nạp","Lấy OTP") -> Lấy OTP | D8: 150000 | F8: =A8&","&D8 -> 901020266,150000
A9: 939250771 | B9: =IF(A9<>"", VLOOKUP(A9,'Danh Sách Tổng KH'!$A$1:$B$547,2,0),"") -> Huỳnh Văn Viển | C9: =IF(E9="x","Đã nạp","Lấy OTP") -> Đã nạp | D9: 100000 | E9: x | F9: =A9&","&D9 -> 939250771,100000
A10: 938242839 | B10: =IF(A10<>"", VLOOKUP(A10,'Danh Sách Tổng KH'!$A$1:$B$547,2,0),"") -> Lê Hoàng Dũng | C10: =IF(E10="x","Đã nạp","Lấy OTP") -> Đã nạp | D10: 150000 | E10: x | F10: =A10&","&D10 -> 938242839,150000
A11: 939197722 | B11: =IF(A11<>"", VLOOKUP(A11,'Danh Sách Tổng KH'!$A$1:$B$547,2,0),"") -> Lê Hoàng Việt | C11: =IF(E11="x","Đã nạp","Lấy OTP") -> Đã nạp | D11: 200000 | E11: x | F11: =A11&","&D11 -> 939197722,200000
A12: 939409049 | B12: =IF(A12<>"", VLOOKUP(A12,'Danh Sách Tổng KH'!$A$1:$B$547,2,0),"") -> Lê Thanh Hên | C12: =IF(E12="x","Đã nạp","Lấy OTP") -> Lấy OTP | D12: 200000 | F12: =A12&","&D12 -> 939409049,200000
A13: 902071313 | B13: =IF(A13<>"", VLOOKUP(A13,'Danh Sách Tổng KH'!$A$1:$B$547,2,0),"") -> Ngô Hồng Duẫn | C13: =IF(E13="x","Đã nạp","Lấy OTP") -> Lấy OTP | D13: 150000 | F13: =A13&","&D13 -> 902071313,150000
A14: 767575599 | B14: =IF(A14<>"", VLOOKUP(A14,'Danh Sách Tổng KH'!$A$1:$B$547,2,0),"") -> Nguyễn Hữu Lộc | C14: =IF(E14="x","Đã nạp","Lấy OTP") -> Đã nạp | D14: 100000 | E14: x | F14: =A14&","&D14 -> 767575599,100000
A15: 939005459 | B15: =IF(A15<>"", VLOOKUP(A15,'Danh Sách Tổng KH'!$A$1:$B$547,2,0),"") -> Dương Thành Phước | C15: =IF(E15="x","Đã nạp","Lấy OTP") -> Lấy OTP | D15: 150000 | F15: =A15&","&D15 -> 939005459,150000
A16: 936401887 | B16: =IF(A16<>"", VLOOKUP(A16,'Danh Sách Tổng KH'!$A$1:$B$547,2,0),"") -> Nguyễn Thanh Hải | C16: =IF(E16="x","Đã nạp","Lấy OTP") -> Đã nạp | D16: 150000 | E16: x | F16: =A16&","&D16 -> 936401887,150000
A17: 909995423 | B17: =IF(A17<>"", VLOOKUP(A17,'Danh Sách Tổng KH'!$A$1:$B$547,2,0),"") -> Nguyễn Thị Hồng Hạnh | C17: =IF(E17="x","Đã nạp","Lấy OTP") -> Lấy OTP | D17: 150000 | F17: =A17&","&D17 -> 909995423,150000
A18: 931894540 | B18: =IF(A18<>"", VLOOKUP(A18,'Danh Sách Tổng KH'!$A$1:$B$547,2,0),"") -> Nguyễn Trọng Hiếu | C18: =IF(E18="x","Đã nạp","Lấy OTP") -> Lấy OTP | D18: 300000 | F18: =A18&","&D18 -> 931894540,300000
A19: 766838368 | B19: =IF(A19<>"", VLOOKUP(A19,'Danh Sách Tổng KH'!$A$1:$B$547,2,0),"") -> Nguyễn Trọng Nhân | C19: =IF(E19="x","Đã nạp","Lấy OTP") -> Lấy OTP | D19: 150000 | F19: =A19&","&D19 -> 766838368,150000
A20: 788791978 | B20: =IF(A20<>"", VLOOKUP(A20,'Danh Sách Tổng KH'!$A$1:$B$547,2,0),"") -> Nguyễn Tuyết My | C20: =IF(E20="x","Đã nạp","Lấy OTP") -> Lấy OTP | D20: 100000 | F20: =A20&","&D20 -> 788791978,100000
A21: 931066039 | B21: =IF(A21<>"", VLOOKUP(A21,'Danh Sách Tổng KH'!$A$1:$B$547,2,0),"") -> Nguyễn Văn Trường | C21: =IF(E21="x","Đã nạp","Lấy OTP") -> Lấy OTP | D21: 150000 | F21: =A21&","&D21 -> 931066039,150000
A22: 931110377 | B22: =IF(A22<>"", VLOOKUP(A22,'Danh Sách Tổng KH'!$A$1:$B$547,2,0),"") -> Lê Thị Kim Thoa | C22: =IF(E22="x","Đã nạp","Lấy OTP") -> Lấy OTP | D22: 100000 | F22: =A22&","&D22 -> 931110377,100000
A23: 939999545 | B23: =IF(A23<>"", VLOOKUP(A23,'Danh Sách Tổng KH'!$A$1:$B$547,2,0),"") -> Trần Kim Hiệp | C23: =IF(E23="x","Đã nạp","Lấy OTP") -> Lấy OTP | D23: 50000 | F23: =A23&","&D23 -> 939999545,50000
A24: 932321231 | B24: =IF(A24<>"", VLOOKUP(A24,'Danh Sách Tổng KH'!$A$1:$B$547,2,0),"") -> Trần Phước Thọ | C24: =IF(E24="x","Đã nạp","Lấy OTP") -> Lấy OTP | D24: 150000 | F24: =A24&","&D24 -> 932321231,150000
A25: 903887662 | B25: =IF(A25<>"", VLOOKUP(A25,'Danh Sách Tổng KH'!$A$1:$B$547,2,0),"") -> Trần Quang Dũng | C25: =IF(E25="x","Đã nạp","Lấy OTP") -> Lấy OTP | D25: 100000 | F25: =A25&","&D25 -> 903887662,100000
A26: 907656592 | B26: =IF(A26<>"", VLOOKUP(A26,'Danh Sách Tổng KH'!$A$1:$B$547,2,0),"") -> Trần Thị Ngọc Trang | C26: =IF(E26="x","Đã nạp","Lấy OTP") -> Lấy OTP | D26: 100000 | F26: =A26&","&D26 -> 907656592,100000
A27: 907969197 | B27: =IF(A27<>"", VLOOKUP(A27,'Danh Sách Tổng KH'!$A$1:$B$547,2,0),"") -> Trương Minh Anh | C27: =IF(E27="x","Đã nạp","Lấy OTP") -> Lấy OTP | D27: 100000 | F27: =A27&","&D27 -> 907969197,100000
A28: 907885586 | B28: =IF(A28<>"", VLOOKUP(A28,'Danh Sách Tổng KH'!$A$1:$B$547,2,0),"") -> Võ Thị Như Trang | C28: =IF(E28="x","Đã nạp","Lấy OTP") -> Lấy OTP | D28: 150000 | F28: =A28&","&D28 -> 907885586,150000
... A80: 939202935 | B80: =IF(A80<>"", VLOOKUP(A80,'Danh Sách Tổng KH'!$A$1:$B$547,2,0),"") -> Nguyễn Thị Ngọc Lyl | C80: =IF(E80="x","Đã nạp","Lấy OTP") -> Lấy OTP | D80: 400000 | F80: =A80&","&D80 -> 939202935,400000

Sheet Trạng thái Đơn Nạp hộ
A1: ="TRANG KIỂM TRA TRẠNG THÁI CHO CHẠY NẠP HỘ TRONG THÁNG " &MONTH(TODAY()) -> TRANG KIỂM TRA TRẠNG THÁI CHO CHẠY NẠP HỘ TRONG THÁNG 10
A2: SĐT | B2: Tên Khách Hàng | C2: Trạng Thái | D2: Số Tiền | E2: Thành công
A3: 939946379 | B3: =IF(A3<>"", VLOOKUP(A3,'Danh Sách Tổng KH'!$A$1:$B$547,2,0),"") -> Võ Anh Hoàng | C3: =IF(E3="x","Đã nạp","Chưa nạp") -> Chưa nạp | D3: 200000 | F3: =A3&","&D3 -> 939946379,200000
A4: 932929119 | B4: =IF(A4<>"", VLOOKUP(A4,'Danh Sách Tổng KH'!$A$1:$B$547,2,0),"") -> Phạm Hoài Nam | C4: =IF(E4="x","Đã nạp","Chưa nạp") -> Chưa nạp | D4: 200000 | F4: =A4&","&D4 -> 932929119,200000
A5: 786999679 | B5: =IF(A5<>"", VLOOKUP(A5,'Danh Sách Tổng KH'!$A$1:$B$547,2,0),"") -> Trân nguyen thanh nam | C5: =IF(E5="x","Đã nạp","Chưa nạp") -> Chưa nạp | D5: 150000 | F5: =A5&","&D5 -> 786999679,150000
A6: 778112338 | B6: =IF(A6<>"", VLOOKUP(A6,'Danh Sách Tổng KH'!$A$1:$B$547,2,0),"") -> Huỳnh Thành Phước | C6: =IF(E6="x","Đã nạp","Chưa nạp") -> Chưa nạp | D6: 250000 | F6: =A6&","&D6 -> 778112338,250000
A7: 901044933 | B7: =IF(A7<>"", VLOOKUP(A7,'Danh Sách Tổng KH'!$A$1:$B$547,2,0),"") -> Dương Thanh Vinh | C7: =IF(E7="x","Đã nạp","Chưa nạp") -> Chưa nạp | D7: 100000 | F7: =A7&","&D7 -> 901044933,100000
A8: 762888832 | B8: =IF(A8<>"", VLOOKUP(A8,'Danh Sách Tổng KH'!$A$1:$B$547,2,0),"") -> Nguyễn Minh Hoàng | C8: =IF(E8="x","Đã nạp","Chưa nạp") -> Chưa nạp | D8: 150000 | F8: =A8&","&D8 -> 762888832,150000
A9: 907022499 | B9: =IF(A9<>"", VLOOKUP(A9,'Danh Sách Tổng KH'!$A$1:$B$547,2,0),"") -> Lại Diễm Trường | C9: =IF(E9="x","Đã nạp","Chưa nạp") -> Chưa nạp | D9: 200000 | F9: =A9&","&D9 -> 907022499,200000
A10: 907965948 | B10: =IF(A10<>"", VLOOKUP(A10,'Danh Sách Tổng KH'!$A$1:$B$547,2,0),"") -> Nguyễn Kim Quang | C10: =IF(E10="x","Đã nạp","Chưa nạp") -> Chưa nạp | D10: 100000 | F10: =A10&","&D10 -> 907965948,100000
A11: 939999196 | B11: =IF(A11<>"", VLOOKUP(A11,'Danh Sách Tổng KH'!$A$1:$B$547,2,0),"") -> Mai Phẩm Chất | C11: =IF(E11="x","Đã nạp","Chưa nạp") -> Chưa nạp | D11: 50000 | F11: =A11&","&D11 -> 939999196,50000
A12: 903026739 | B12: =IF(A12<>"", VLOOKUP(A12,'Danh Sách Tổng KH'!$A$1:$B$547,2,0),"") -> Phạm Thanh Việt | C12: =IF(E12="x","Đã nạp","Chưa nạp") -> Chưa nạp | D12: 50000 | F12: =A12&","&D12 -> 903026739,50000
A13: 908888514 | B13: =IF(A13<>"", VLOOKUP(A13,'Danh Sách Tổng KH'!$A$1:$B$547,2,0),"") -> Trần Thị Thanh Thảo | C13: =IF(E13="x","Đã nạp","Chưa nạp") -> Chưa nạp | D13: 50000 | F13: =A13&","&D13 -> 908888514,50000
A14: 903333938 | B14: =IF(A14<>"", VLOOKUP(A14,'Danh Sách Tổng KH'!$A$1:$B$547,2,0),"") -> Đặng Thanh Phong | C14: =IF(E14="x","Đã nạp","Chưa nạp") -> Chưa nạp | D14: 150000 | F14: =A14&","&D14 -> 903333938,150000
... A181: 901093686 | B181: =IF(A181<>"", VLOOKUP(A181,'Danh Sách Tổng KH'!$A$1:$B$547,2,0),"") -> Huỳnh Anh Tuấn | C181: =IF(E181="x","Đã nạp","Chưa nạp") -> Chưa nạp | D181: 150000 | F181: =A181&","&D181 -> 901093686,150000
